Workbook

Sheet Resumen
A1: Pase de lista automático con escáner facial: ventajas, desventajas y evidencia
A2: Preparado el 06-oct-2026 con datos de INEGI/SEP, RNPDNO, CIDH, NIST, Banco Mundial, RAND y reguladores internacionales.
A4: Conclusiones clave
A5: 1. La NECESIDAD está muy bien documentada: el abandono escolar subió en primaria, secundaria y media superior (2019-20 a 2023-24) y hay más de 18 mil NNA desaparecidos o no localizados.
A6: 2. Seguridad escolar: el caso Rébsamen (26 fallecidos) y 2,224 escuelas dañadas en 2017 muestran el valor de un registro confiable de presentes.
A7: 3. Lo que sí hay evidencia internacional: avisar rápido y dar seguimiento mejora asistencia (p. ej., 48.4% de alumnos regresó tras una carta), pero el monitoreo sin consecuencias no funcionó (India).
A8: 4. Vacío importante: no encontramos estudios que midan que el reconocimiento facial sea MEJOR que RFID, QR o huella para pasar lista en escuelas. Esa diferencia es un argumento de diseño (anti-suplantación y rapidez).
A9: 5. Mayor riesgo: biometría de menores. Suecia multó una escuela por un piloto de asistencia facial (22 alumnos); el Reino Unido y Francia también intervinieron. En México, el marco legal está en transición.
A10: 6. Recomendación: presentar el proyecto como 'facial con salvaguardas' (opt-in, alternativa no biométrica, plantillas cifradas, validación del profesor, protocolo escalonado de alertas) y medir resultados con un piloto.
A12: Indicadores clave (enlazados a las hojas de datos)
A13: Indicador | B13: Valor | C13: Fuente / contexto
A14: Abandono escolar media superior 2023-24 | B14: =Datos_Mexico!C16 -> 0.113 | C14: SEP/INEGI (S01, S02)
A15: Aumento del abandono en media superior vs 2019-20 (pp) | B15: =Datos_Mexico!C17 -> 1 | C15: Cálculo sobre S02
A16: Aumento relativo del abandono en primaria | B16: =Datos_Mexico!C10 -> 0.5 | C16: Cálculo sobre S02
A17: NNA desaparecidos o no localizados (8-jun-2026) | B17: =Datos_Mexico!C27 -> 18104 | C17: RNPDNO vía S07
A18: Proporción: mujeres de 12 a 17 años | B18: =Datos_Mexico!C29 -> 0.36925541 | C18: Cálculo sobre S07
A19: Escuelas dañadas por los sismos de sep-2017 | B19: =Datos_Mexico!C46 -> 2224 | C19: SEP vía S12
A20: Fallecidos en el Colegio Rébsamen | B20: =Datos_Mexico!C50 -> 26 | C20: S14
A21: Exceso de ausentismo crónico EE.UU. vs prepandemia (pp) | B21: =Datos_Internacional!C9 -> 6.8 | C21: RAND (S20)
A22: Docentes ausentes, promedio 6 países | B22: =Datos_Internacional!C22 -> 0.19 | C22: Banco Mundial (S24)
A23: Multa Suecia por asistencia facial (SEK) | B23: =Datos_Internacional!C37 -> 200000 | C23: IMY (S29)
A25: Datos para gráfico: abandono por nivel
A26: Nivel | B26: 2019-20 | C26: 2023-24
A27: Primaria | B27: =Datos_Mexico!C7 -> 0.004 | C27: =Datos_Mexico!C8 -> 0.006
A28: Secundaria | B28: =Datos_Mexico!C11 -> 0.027 | C28: =Datos_Mexico!C12 -> 0.037
A29: Media superior | B29: =Datos_Mexico!C15 -> 0.103 | C29: =Datos_Mexico!C16 -> 0.113
A49: Guía de colores: azul = dato capturado; negro = fórmula; verde = enlace a otra hoja; amarillo = supuesto editable.
A50: Aviso: este documento es informativo y no constituye asesoría legal. Verifique la normativa vigente de protección de datos con un abogado antes de implementar.

Sheet Ventajas
A1: Ventajas de su sistema, con datos que las respaldan
A2: Se separa 'respalda la NECESIDAD' (datos reales) de 'respalda la EFICACIA del sistema' (lo que realmente demuestra que su solución funciona).
A4: # | B4: Ventaja (su redacción) | C4: Dato(s) de respaldo | D4: Respalda la NECESIDAD | E4: Respalda la EFICACIA del sistema | F4: Diferencia frente a otros sistemas (papel, RFID/QR, huella) | G4: Indicador para medir su éxito | H4: Fuentes | I4: Advertencia / límite de la evidencia
A5: 1 | B5: Constancia de entrada tanto del alumnado como profesorado | C5: Ausentismo docente promedio de 19% en 6 países (visitas sorpresa, Banco Mundial); 25% en India. En EE.UU. 22.6% del alumnado tiene ausentismo crónico (2024-25), 7 pp sobre la prepandemia. En México la SEP no actualiza el abandono desde 2023-24, por lo que no hay registro oficial reciente a nivel plantel. | D5: Alta | E5: Parcial | F5: Frente a papel: dato con hora exacta y no editable. Frente a RFID/QR: la persona es la credencial, no se presta. Frente a huella: sin contacto físico y más rápido en filas. | G5: % de puntualidad; días-alumno ausentes; horas-docente efectivas vs programadas; % de registros corregidos manualmente. | H5: S24, S25, S19, S20, S02 | I5: El monitoreo solo funcionó en India cuando había incentivos/consecuencias (S23). No existe estudio que compare facial vs RFID en escuelas: la diferencia es un argumento de diseño, no un resultado medido.
A6: 2 | B6: En caso de incidentes tener constancia de los individuos presentes en las instalaciones | C6: Rébsamen (2017): 26 fallecidos (19 niños, 7 adultos); en las primeras horas las cifras oficiales variaron de 21 a 37. Más de 2,224 escuelas dañadas y 31 escuelas con permiso revocado en CDMX por no garantizar seguridad. | D6: Alta | E6: Parcial | F6: El papel se pierde o queda dentro del edificio colapsado; un registro en servidor externo con hora de entrada sobrevive al incidente. | G6: Tiempo para producir la lista de presentes (meta < 2 min); % de coincidencia con conteo físico en simulacros. | H6: S12, S13, S14 | I6: Registra la ENTRADA, no la ubicación actual: alguien pudo salir antes. Complementar con conteo en punto de reunión.
A7: 3 | B7: Notificación de entrada y salida del alumnado para el profesor en turno | C7: El ausentismo crónico se duplica de 5.º grado (14.2%) a 12.º grado (32.1%). Distritos con estrategias proactivas: 20.9% vs 23.5% nacional. 48.4% de los alumnos regresó tras una sola carta de aviso. En México la deserción en media superior es 11.3% (2023-24) y subió en los tres niveles desde 2019-20. | D7: Alta | E7: Media | F7: Frente al pase manual: el profesor recibe el dato sin gastar tiempo de clase (ver hoja Calculadora). Frente a RFID/QR: detecta presencia real de la persona. | G7: Tiempo de pase de lista; % de alumnos con 3+ faltas detectados en < 48 h; tasa de abandono por grupo. | H7: S22, S02, S01 | I7: El dato de 48.4% proviene de un proveedor comercial (S22) y de correlación, no de experimento. Útil como orden de magnitud.
A8: 4 | B8: Proporciona seguridad en caso de algún desastre natural | C8: Sismo 2017: 14 millones de estudiantes sin clases; 1,901 de 2,800 planteles básicos de CDMX con daños (68%). 18,868 alumnos (1.6% de CDMX) seguían en aulas provisionales un año después. | D8: Alta | E8: Parcial / No demostrada | F8: Un registro digital reemplaza listas impresas que no se pueden consultar con el edificio inaccesible; permite a protección civil saber cuántos y quiénes pueden estar adentro. | G8: % de exactitud del listado vs conteo manual en simulacro; tiempo de entrega del listado a protección civil. | H8: S12, S13 | I8: No hay evidencia publicada de que un sistema automático de asistencia reduzca víctimas. Debe tener modo offline y respaldo sin energía/Internet.
A9: 5 | B9: Notificación inmediata en caso de falta total de algún alumno para avisar a tutores y autoridades (caso de desaparición) | C9: 18,104 NNA desaparecidos o no localizados (8-jun-2026); 6,685 son mujeres de 12-17 años (36.9%). Más de 5 NNA desaparecen cada día. 28% de los niños desaparecidos en 2026 seguían sin localizar a abril. Las adolescentes mujeres tienen más de 90% de localización, lo que sugiere que actuar rápido es viable. | D9: Alta | E9: Parcial | F9: Frente al pase manual: reduce el tiempo entre la inasistencia y el aviso al tutor, que depende del profesor y de la hora. Frente a RFID/QR: confirma la persona, no la tarjeta. | G9: Minutos entre la hora de entrada esperada y el aviso al tutor; % de avisos que resultan falsas alarmas. | H9: S07, S08, S06, S10 | I9: Una inasistencia casi nunca es una desaparición: requiere protocolo escalonado (llamada, verificación, escalamiento). Evita alarmas falsas masivas. No hay estudio que mida cuántos casos evitaría.
A10: 6* | B10: Ahorro de tiempo docente en el pase de lista (ventaja adicional sugerida) | C10: Con supuestos editables (hoja Calculadora): 20 grupos x 6 clases x 4 min x 185 días = miles de horas por año por plantel. | D10: Media | E10: Media | F10: Es la ventaja más fácil de medir y la que más rápido se percibe. | G10: Minutos de pase de lista por clase antes vs después. | H10: Calculadora | I10: Depende de los supuestos que usted capture: reemplácelos por mediciones reales de su escuela.
A11: 7* | B11: Alerta temprana de abandono escolar (ventaja adicional sugerida) | C11: Abandono 2019-20 vs 2023-24: primaria 0.4% a 0.6% (+50%); secundaria 2.7% a 3.7% (+37%); media superior 10.3% a 11.3%. | D11: Alta | E11: Media | F11: Convierte el dato de asistencia en un indicador acumulado por alumno, algo que ni el papel ni la tarjeta producen con facilidad. | G11: % de alumnos en riesgo identificados antes de reprobar o desertar; reincorporaciones. | H11: S02, S03 | I11: Requiere que la escuela actúe sobre la alerta (tutoría, visita a familias).
A12: 8* | B12: Auditoría de horas docentes y puntualidad del profesorado (ventaja adicional sugerida) | C12: 19% de ausencia docente promedio en 6 países; 35% de tiempo perdido en línea base en India (Seva Mandir). | D12: Media | E12: Media | F12: Evita 'firmas por favor' y registros inflados; la validación biométrica es más difícil de falsificar. | G12: % de clases iniciadas a tiempo; horas efectivas vs plan. | H12: S24, S23 | I12: Tema laboral sensible: defina por escrito el uso del dato con sindicatos/dirección.
A14: * Ventajas adicionales propuestas; las cinco primeras son las de su lista original.
A15: Lectura honesta: los datos prueban con claridad que el problema es real y grave. Lo que NO existe (en las fuentes consultadas) es un estudio que demuestre que el reconocimiento facial supera a RFID/QR/huella para tomar asistencia escolar. Presentarlo así ante autoridades o inversionistas lo hará más creíble.

Sheet Desventajas
A1: Desventajas y riesgos, con datos y mitigaciones
A3: # | B3: Desventaja / riesgo | C3: Dato o precedente | D3: Gravedad | E3: Mitigación recomendada | F3: Fuentes
A4: 1 | B4: Biometría de menores: dato personal sensible y alto riesgo legal | C4: Suecia multó con SEK 200,000 (~€20,000) a una escuela por usar reconocimiento facial para asistencia (22 alumnos, 3 semanas). Reino Unido: reprimenda del ICO en 2024. Francia: la CNIL se opuso a pilotos en liceos. | D4: Alta | E4: Evaluación de impacto en protección de datos antes de operar; minimizar datos; aviso de privacidad claro; consulta a autoridad y a padres/alumnos. | F4: S29, S31, S32
A5: 2 | B5: El consentimiento puede no ser válido por desequilibrio de poder | C5: La autoridad sueca consideró inválido el consentimiento aunque lo firmaron alumnos y padres: el alumno depende de la escuela. | D5: Alta | E5: Ofrecer alternativa NO biométrica (tarjeta/QR) con el mismo derecho; consentimiento libre, específico y revocable; opt-in, no opt-out. | F5: S29, S30
A6: 3 | B6: Marco legal mexicano en transición | C6: Nueva LFPDPPP en vigor desde 21-mar-2025 (aplica a escuelas privadas); el INAI desapareció y la autoridad es ahora la Secretaría Anticorrupción y Buen Gobierno. Escuelas públicas: Ley General de Protección de Datos Personales en Posesión de Sujetos Obligados. Existe una INICIATIVA para tratar expresamente como sensibles los datos biométricos (no verificada como vigente). | D6: Alta | E6: Asesoría jurídica antes de implementar; aviso de privacidad integral; documentar finalidad, retención y transferencias. | F6: S15, S16, S17
A7: 4 | B7: Falsos positivos/negativos mayores en niños | C7: NIST: mayoría de algoritmos con diferenciales demográficos; mayor falso positivo en niños y ancianos. Muchos algoritmos logran 98-99% de exactitud en todos los grupos, pero los peores muestran diferenciales >100x. | D7: Media | E7: Exigir al proveedor métricas con población infantil/adolescente mexicana; umbral conservador; revisión humana (su diseño ya incluye validación del profesor). | F7: S27, S28
A8: 5 | B8: Fuga de datos biométricos es irreversible | C8: Principio general de ciberseguridad: una contraseña se cambia, un rostro no. (Sin cifra específica en esta compilación.) | D8: Alta | E8: Guardar plantillas matemáticas cifradas (no fotos), idealmente en dispositivo local; borrado al egresar; acceso por roles y bitácora. | F8: Principio general
A9: 6 | B9: Los falsos positivos de desaparición pueden saturar a familias y autoridades | C9: Una inasistencia casi nunca es una desaparición. Sin protocolo, el aviso inmediato puede generar fatiga de alertas. (Sin cifra publicada en las fuentes consultadas.) | D9: Media | E9: Protocolo escalonado: aviso interno, llamada a tutor, segunda verificación, y solo entonces escalar a autoridades. | F9: Criterio de diseño
A10: 7 | B10: La tecnología sola no mejora la asistencia | C10: En India el monitoreo de docentes no funcionó sin incentivos o sanciones; el efecto de monitores biométricos en centros de salud fue limitado y se debilitó. | D10: Media | E10: Definir qué hace la escuela con el dato: tutoría, apoyo a familias, reconocimiento a la puntualidad. | F10: S23
A11: 8 | B11: Registra entradas, no la ubicación en una emergencia; depende de energía y conectividad | C11: Un alumno que salió antes figura 'presente' hasta que se registra la salida. En un desastre puede fallar la red eléctrica o Internet. | D11: Media | E11: Modo offline con sincronización; respaldo impreso/exportable; conteo físico en punto de reunión; registrar también salidas. | F11: Criterio de diseño
A12: 9 | B12: Falsos negativos por calidad de imagen (iluminación, crecimiento, lesiones, accesorios) | C12: NIST: mejor calidad de imagen reduce falsos negativos y diferenciales. | D12: Media | E12: Re-enrolamiento periódico para menores en crecimiento; estación con buena luz; flujo manual de excepciones. | F12: S27
A13: 10 | B13: Costo, infraestructura y brecha entre escuelas | C13: Dato pendiente: no se incluyó cifra de costo ni de conectividad escolar. Recomendamos consultar INEGI (ENDUTIH) y el Censo de Escuelas para dimensionar. | D13: Media | E13: Piloto en un plantel con métricas de costo por alumno; versión ligera sin nube para planteles con poca conectividad. | F13: Pendiente
A14: 11 | B14: Rechazo social y efecto de vigilancia | C14: La CNIL señaló que el control facial intensifica la sensación de vigilancia en menores. | D14: Media | E14: Comunicación transparente, comité con padres, uso limitado a asistencia (no disciplina ni analítica de comportamiento). | F14: S32
A15: 12 | B15: Falta de línea base oficial en México para medir impacto | C15: La SEP no ha actualizado el SIGED con abandono desde el ciclo 2023-24. | D15: Baja | E15: Registrar su propia línea base 4-6 semanas antes de activar el sistema. | F15: S02

Sheet Casos_de_uso
A1: Casos en que un pase de lista confiable es indispensable
A3: # | B3: Caso de uso | C3: Qué aporta el pase de lista | D3: Dato de contexto | E3: Criticidad | F3: Condición para que funcione | G3: Fuentes
A4: 1 | B4: Sismo y evacuación | C4: Lista inmediata de quién entró y quién debería estar en el punto de reunión. | D4: Rébsamen 2017: 26 fallecidos; 2,224 escuelas dañadas; 14 millones de alumnos sin clases. | E4: Crítica | F4: Modo offline; conteo físico en punto de reunión; simulacros periódicos. | G4: S12, S13, S14
A5: 2 | B5: Incendio o fuga de gas | C5: Permite al personal de emergencia saber cuántas personas pueden seguir en el edificio. | D5: Principio operativo (sin estadística específica en esta compilación). | E5: Crítica | F5: Listado accesible desde un dispositivo fuera del edificio. | G5: Criterio de diseño
A6: 3 | B6: Ausencia total de un menor (posible desaparición) | C6: Detecta la no llegada y activa el aviso al tutor en minutos. | D6: 18,104 NNA no localizados; más de 5 NNA desaparecen cada día; las adolescentes de 12-17 son el grupo más afectado. | E6: Crítica | F6: Protocolo de verificación escalonado y convenio con autoridades. | G6: S07, S08, S10
A7: 4 | B7: Amenaza armada / encierro (lockdown) | C7: Conocer quién está dentro y quién no, para el equipo de respuesta. | D7: Principio operativo (sin estadística específica en esta compilación). | E7: Alta | F7: Integración con protocolo de seguridad escolar. | G7: Criterio de diseño
A8: 5 | B8: Alerta temprana de abandono escolar | C8: Patrones de faltas por alumno para intervenir antes de la deserción. | D8: Abandono en media superior: 11.3% (2023-24); aumentó en primaria, secundaria y media superior desde 2019-20. Una sola carta recuperó al 48.4% de alumnos (EE.UU.). | E8: Alta | F8: Equipo de tutoría que actúe sobre las alertas. | G8: S02, S22
A9: 6 | B9: Control de puntualidad y horas docentes | C9: Registro objetivo de entrada del profesorado. | D9: Docentes ausentes: 19% en 6 países; 25% en India; mejoras solo con consecuencias. | E9: Media | F9: Política laboral clara y acordada. | G9: S24, S23
A10: 7 | B10: Accidentes o lesiones dentro del plantel | C10: Confirmar quién estaba presente y en qué horario, para atención y seguro escolar. | D10: Principio operativo. | E10: Media | F10: Retención limitada de registros. | G10: Criterio de diseño
A11: 8 | B11: Brotes de enfermedades (rastreo de contactos) | C11: Identificar quién coincidió en el plantel. | D11: Principio operativo; evaluar con salud pública. | E11: Media | F11: Uso excepcional y justificado de los datos. | G11: Criterio de diseño
A12: 9 | B12: Aclaración de responsabilidades legales | C12: Evidencia objetiva de presencia y horarios ante procesos legales o de protección civil. | D12: En CDMX se revocó el permiso a 31 escuelas por no garantizar seguridad ante emergencias; el caso Rébsamen derivó en procesos judiciales y disculpa pública. | E12: Alta | F12: Bitácora inalterable y cadena de custodia. | G12: S14
A13: 10 | B13: Control de salida y entrega a tutores autorizados (extensión) | C13: Verificar que el menor sale con una persona autorizada. | D13: Extensión propuesta; implica más datos biométricos (los del tutor): evaluar con asesoría jurídica. | E13: Media | F13: Lista de autorizados y consentimiento de cada tutor. | G13: Criterio de diseño

Sheet Comparativa
A1: Comparativa de sistemas de pase de lista (evaluación cualitativa)
A2: ATENCIÓN: los puntajes (1-5) son juicio del analista, NO provienen de INEGI ni de un estudio. Edite las celdas amarillas (pesos y puntajes) con su criterio o datos de proveedor.
A4: Criterio (5 = mejor) | B4: Peso | C4: Lista en papel | D4: Lista manual en app | E4: Tarjeta RFID/NFC | F4: Código QR | G4: Huella dactilar | H4: Facial (como está) | I4: Facial con salvaguardas*
A5: Anti-suplantación (nadie registra por otro) | B5: 0.2 | C5: 1 | D5: 1 | E5: 2 | F5: 2 | G5: 4 | H5: 5 | I5: 5
A6: Rapidez / baja fricción en la entrada | B6: 0.15 | C6: 1 | D6: 2 | E6: 4 | F6: 3 | G6: 3 | H6: 5 | I6: 5
A7: Costo bajo | B7: 0.15 | C7: 5 | D7: 4 | E7: 3 | F7: 4 | G7: 2 | H7: 2 | I7: 2
A8: Privacidad / bajo riesgo legal | B8: 0.2 | C8: 5 | D8: 5 | E8: 4 | F8: 4 | G8: 2 | H8: 1 | I8: 3
A9: Precisión del registro | B9: 0.1 | C9: 2 | D9: 3 | E9: 3 | F9: 3 | G9: 4 | H9: 4 | I9: 4
A10: Utilidad en emergencia (registro automático de presentes) | B10: 0.1 | C10: 2 | D10: 3 | E10: 4 | F10: 3 | G10: 4 | H10: 5 | I10: 5
A11: Robustez sin energía / Internet | B11: 0.1 | C11: 5 | D11: 3 | E11: 3 | F11: 3 | G11: 2 | H11: 2 | I11: 2
A12: Suma de pesos (debe ser 100%) | B12: =SUM(B5:B11) -> 1
A13: Puntaje ponderado (máx. 5.0) | C13: =SUMPRODUCT($B$5:$B$11,C5:C11) -> 3 | D13: =SUMPRODUCT($B$5:$B$11,D5:D11) -> 3 | E13: =SUMPRODUCT($B$5:$B$11,E5:E11) -> 3.25 | F13: =SUMPRODUCT($B$5:$B$11,F5:F11) -> 3.15 | G13: =SUMPRODUCT($B$5:$B$11,G5:G11) -> 2.95 | H13: =SUMPRODUCT($B$5:$B$11,H5:H11) -> 3.35 | I13: =SUMPRODUCT($B$5:$B$11,I5:I11) -> 3.75
A14: Lugar (1 = mejor) | C14: =RANK(C13,$C$13:$I$13) -> 5 | D14: =RANK(D13,$C$13:$I$13) -> 5 | E14: =RANK(E13,$C$13:$I$13) -> 3 | F14: =RANK(F13,$C$13:$I$13) -> 4 | G14: =RANK(G13,$C$13:$I$13) -> 7 | H14: =RANK(H13,$C$13:$I$13) -> 2 | I14: =RANK(I13,$C$13:$I$13) -> 1
A16: * 'Facial con salvaguardas' = opt-in con alternativa no biométrica, plantilla cifrada local, evaluación de impacto, validación humana y retención limitada.
A17: Lectura: con los pesos por defecto, el facial 'tal cual' NO gana: su ventaja en anti-suplantación y rapidez se compensa con privacidad y costo. Con salvaguardas sube de lugar. Es el argumento más sólido para su proyecto.
A18: Cambie los pesos según su prioridad (p. ej., si su escuela prioriza seguridad ante desapariciones, aumente 'Utilidad en emergencia').
A19: No existe en las fuentes consultadas un estudio comparativo de estos sistemas en escuelas; esta tabla estructura la decisión, no la sustituye por datos.

Sheet Datos_Mexico
A1: Datos de México (INEGI / SEP / RNPDNO / CIDH)
A2: Valores en azul = dato capturado de la fuente. Valores en negro = fórmula calculada. Consulta: 06-oct-2026.
A4: ID | B4: Indicador | C4: Valor | D4: Unidad | E4: Periodo / corte | F4: Fuente | G4: Ventaja relacionada | H4: Nota / advertencia
A5: A. Educación: matrícula y abandono escolar (justifica ventajas 1 y 3 + alerta temprana)
A6: M01 | B6: Matrícula escolar total (todos los niveles) | C6: 33062447 | D6: alumnos | E6: Ciclo 2023-24 | F6: S04 | G6: 1, 3 | H6: Universo que debería registrarse. INEGI/SEP.
A7: M-P0 | B7: Tasa de abandono escolar - primaria | C7: 0.004 | D7: % de matrícula | E7: Ciclo 2019-20 | F7: S02, S03 | G7: 3 | H7: Cifra SEP/SIGED reportada por Expansión.
A8: M-P1 | B8: Tasa de abandono escolar - primaria | C8: 0.006 | D8: % de matrícula | E8: Ciclo 2023-24 | F8: S02, S03 | G8: 3 | H8: Último ciclo publicado; la SEP no ha actualizado el SIGED desde entonces.
A9: M-P2 | B9: Variación absoluta - primaria | C9: =(C8-C7)*100 -> 0.2 | D9: pp | E9: 2019-20 a 2023-24 | F9: Cálculo | G9: 3 | H9: Puntos porcentuales.
A10: M-P3 | B10: Variación relativa - primaria | C10: =C8/C7-1 -> 0.5 | D10: % | E10: 2019-20 a 2023-24 | F10: Cálculo | G10: 3 | H10: Crecimiento relativo del abandono.
A11: M-S0 | B11: Tasa de abandono escolar - secundaria | C11: 0.027 | D11: % de matrícula | E11: Ciclo 2019-20 | F11: S02, S03 | G11: 3 | H11: Cifra SEP/SIGED reportada por Expansión.
A12: M-S1 | B12: Tasa de abandono escolar - secundaria | C12: 0.037 | D12: % de matrícula | E12: Ciclo 2023-24 | F12: S02, S03 | G12: 3 | H12: Último ciclo publicado; la SEP no ha actualizado el SIGED desde entonces.
A13: M-S2 | B13: Variación absoluta - secundaria | C13: =(C12-C11)*100 -> 1 | D13: pp | E13: 2019-20 a 2023-24 | F13: Cálculo | G13: 3 | H13: Puntos porcentuales.
A14: M-S3 | B14: Variación relativa - secundaria | C14: =C12/C11-1 -> 0.37037037 | D14: % | E14: 2019-20 a 2023-24 | F14: Cálculo | G14: 3 | H14: Crecimiento relativo del abandono.
A15: M-MS0 | B15: Tasa de abandono escolar - media superior | C15: 0.103 | D15: % de matrícula | E15: Ciclo 2019-20 | F15: S02, S03 | G15: 3 | H15: Cifra SEP/SIGED reportada por Expansión.
A16: M-MS1 | B16: Tasa de abandono escolar - media superior | C16: 0.113 | D16: % de matrícula | E16: Ciclo 2023-24 | F16: S02, S03 | G16: 3 | H16: Último ciclo publicado; la SEP no ha actualizado el SIGED desde entonces.
A17: M-MS2 | B17: Variación absoluta - media superior | C17: =(C16-C15)*100 -> 1 | D17: pp | E17: 2019-20 a 2023-24 | F17: Cálculo | G17: 3 | H17: Puntos porcentuales.
A18: M-MS3 | B18: Variación relativa - media superior | C18: =C16/C15-1 -> 0.097087379 | D18: % | E18: 2019-20 a 2023-24 | F18: Cálculo | G18: 3 | H18: Crecimiento relativo del abandono.
A19: M-NOTA | B19: Discrepancia entre fuentes (nota de calidad de datos) | C19: Ver nota | D19: texto | E19: 2023-24 | F19: S33, S01 | G19: 3 | H19: S33 reporta 10.8% (media superior) y 2.9% (secundaria) como cifras INEGI; S02 reporta 11.3% y 3.7%. Verifique con S01 antes de publicar.
A20: M-SEP | B20: Disponibilidad de cifras oficiales actualizadas de abandono | C20: Sin actualizar | D20: texto | E20: desde 2023-24 | F20: S02 | G20: 1, 3 | H20: Oportunidad: un registro propio de asistencia genera datos que hoy no existen a nivel plantel.
A21: B. Niñas, niños y adolescentes desaparecidos o no localizados (justifica ventaja 5)
A22: M10 | B22: Registros acumulados de personas desaparecidas (RNPDNO) | C22: 365024 | D22: personas | E22: 2000 - jun 2026 | F22: S06 | G22: 5 | H22: Incluye localizadas y no localizadas.
A23: M11 | B23: Desapariciones registradas en el año | C23: 12961 | D23: personas | E23: 2025 | F23: S07 | G23: 5 | H23: S05 menciona 'casi 12 mil' con otro corte de consulta; las cifras varían según la fecha de consulta del RNPDNO.
A24: M12 | B24: Promedio diario de personas desaparecidas | C24: 35 | D24: personas/día | E24: 2026 (boletín) | F24: S07 | G24: 5 | H24: Promedio citado por el boletín.
A25: M13 | B25: Niñas, niños y adolescentes entre esas desapariciones diarias (mínimo) | C25: 5 | D25: NNA/día | E25: 2026 (boletín) | F25: S07 | G25: 5 | H25: El boletín dice 'más de cinco'; se usa 5 como mínimo conservador.
A26: M14 | B26: Proporción mínima de NNA en desapariciones diarias | C26: =C25/C24 -> 0.14285714 | D26: % | E26: Cálculo | F26: Cálculo | G26: 5 | H26: Estimación mínima (≥).
A27: M15 | B27: NNA desaparecidos o no localizados (vigentes) | C27: 18104 | D27: NNA | E27: Al 8-jun-2026 | F27: S07 | G27: 5 | H27: Otras fuentes: 18,192 (CIDH, S08) y 18,275 (Gaceta, S11): diferencias por fecha de corte.
A28: M16 | B28: De ellos: mujeres de 12 a 17 años | C28: 6685 | D28: adolescentes | E28: Al 8-jun-2026 | F28: S07 | G28: 5 | H28: Grupo de mayor vulnerabilidad.
A29: M17 | B29: Proporción de mujeres 12-17 dentro de NNA no localizados | C29: =C28/C27 -> 0.36925541 | D29: % | E29: Cálculo | F29: Cálculo | G29: 5 | H29: Más de 1 de cada 3.
A30: M18 | B30: NNA 0-17 desaparecidos (CIDH) | C30: 18192 | D30: NNA | E30: Corte CIDH 2025-26 | F30: S08 | G30: 5
A31: M19 | B31: de los cuales niñas y adolescentes mujeres | C31: 9342 | D31: NNA | E31: Corte CIDH | F31: S08 | G31: 5
A32: M20 | B32: de los cuales niños y adolescentes hombres | C32: 8817 | D32: NNA | E32: Corte CIDH | F32: S08 | G32: 5
A33: M21 | B33: sin sexo especificado (diferencia) | C33: =C30-C31-C32 -> 33 | D33: NNA | E33: Cálculo | F33: Cálculo | G33: 5 | H33: Diferencia entre total y suma por sexo en la fuente.
A34: M22 | B34: Menores desaparecidos - Estado de México | C34: 4113 | D34: NNA | E34: A jun-2025 | F34: S09 | G34: 5 | H34: Entidad con más casos de menores.
A35: M23 | B35: Menores desaparecidos - Ciudad de México | C35: 1583 | D35: NNA | E35: A jun-2025 | F35: S09 | G35: 5
A36: M24 | B36: Reportes de desaparición de NNA (REDIM) | C36: 10700 | D36: reportes (mín.) | E36: 2025 | F36: S08 | G36: 5 | H36: 'Más de 10,700'.
A37: M25 | B37: Niñas y niños desaparecidos en 2026 | C37: 1485 | D37: NNA | E37: Ene-abr 2026 | F37: S08 | G37: 5 | H37: Comisión Nacional de Búsqueda.
A38: M26 | B38: Proporción aún sin localizar | C38: 0.28 | D38: % | E38: A fines de abr-2026 | F38: S08 | G38: 5
A39: M27 | B39: Estimado de NNA sin localizar (2026) | C39: =ROUND(C37*C38,0) -> 416 | D39: NNA | E39: Cálculo | F39: Cálculo | G39: 5 | H39: Aprox. 1 de cada 4 a 3.5 niños.
A40: M28 | B40: Reportes jul-2026: mujeres 15-19 años | C40: 193 | D40: personas | E40: Jul-2026 | F40: S10 | G40: 5 | H40: Grupo con más reportes.
A41: M29 | B41: Reportes jul-2026: hombres 15-19 años | C41: 137 | D41: personas | E41: Jul-2026 | F41: S10 | G41: 5
...

Sheet Datos_Internacional
A1: Datos internacionales: asistencia, ausentismo docente, reconocimiento facial y regulación
A2: Valores en azul = dato capturado. Negro = fórmula. Consulta: 06-oct-2026.
A4: ID | B4: Indicador | C4: Valor | D4: Unidad | E4: Periodo / corte | F4: Fuente | G4: Ventaja relacionada | H4: Nota / advertencia
A5: A. Ausentismo estudiantil crónico (EE.UU.) - referencia de necesidad y de efecto de intervención
A6: I01 | B6: Ausentismo crónico, 44 estados + DC | C6: 0.226 | D6: % de alumnos | E6: 2024-25 | F6: S19 | G6: 1, 3 | H6: Estudio AEI.
A7: I02 | B7: Ausentismo crónico, estimación nacional RAND | C7: 0.218 | D7: % de alumnos | E7: 2024-25 | F7: S20 | G7: 1, 3
A8: I03 | B8: Ausentismo crónico prepandemia | C8: 0.15 | D8: % de alumnos | E8: ~2018-19 | F8: S20 | G8: 1, 3 | H8: Aproximado.
A9: I04 | B9: Exceso sobre nivel prepandemia | C9: =(C7-C8)*100 -> 6.8 | D9: pp | E9: Cálculo | F9: Cálculo | G9: 3
A10: I05 | B10: Ausentismo crónico, 31 estados | C10: 0.29 | D10: % de alumnos | E10: 2021-22 | F10: S18 | G10: 3 | H10: Attendance Works / Johns Hopkins.
A11: I06 | B11: Ausentismo crónico, 31 estados | C11: 0.21 | D11: % de alumnos | E11: 2024-25 | F11: S18 | G11: 3
A12: I07 | B12: Cambio 2021-22 a 2024-25 | C12: =(C11-C10)*100 -> -8 | D12: pp | E12: Cálculo | F12: Cálculo | G12: 3 | H12: Mejora gracias a sistemas de monitoreo y seguimiento (el informe enfatiza enfoque integral, no solo tecnología).
A13: I08 | B13: California: ausentismo crónico | C13: 0.194 | D13: % de alumnos | E13: 2024-25 | F13: S21 | G13: 3 | H13: 1,143,668 alumnos.
A14: I09 | B14: Ausentismo crónico en 5.º grado | C14: 0.1422 | D14: % de alumnos | E14: 2024-25 | F14: S22 | G14: 3 | H14: Fuente comercial (SchoolStatus).
A15: I10 | B15: Ausentismo crónico en 12.º grado | C15: 0.3213 | D15: % de alumnos | E15: 2024-25 | F15: S22 | G15: 3
A16: I11 | B16: Multiplicador 5.º a 12.º grado | C16: =C15/C14 -> 2.2594937 | D16: veces | E16: Cálculo | F16: Cálculo | G16: 3 | H16: El problema crece con la edad: justifica alerta temprana en secundaria/preparatoria.
A17: I12 | B17: Promedio nacional de ausentismo crónico (según SchoolStatus) | C17: 0.235 | D17: % de alumnos | E17: 2024-25 | F17: S22 | G17: 3
A18: I13 | B18: Distritos con estrategias proactivas de asistencia | C18: 0.2092 | D18: % de alumnos | E18: 2024-25 | F18: S22 | G18: 3 | H18: 172 distritos socios; no es experimento aleatorio.
A19: I14 | B19: Diferencia distritos proactivos vs promedio | C19: =(C18-C17)*100 -> -2.58 | D19: pp | E19: Cálculo | F19: Cálculo | G19: 3 | H19: Correlación, no causalidad; fuente con interés comercial.
A20: I15 | B20: Alumnos que regresaron tras UNA carta de intervención | C20: 0.484 | D20: % de alumnos | E20: 2024-25 | F20: S22 | G20: 3 | H20: Aviso oportuno funciona: respalda la notificación inmediata.
A21: B. Ausentismo docente (justifica constancia de entrada del profesorado)
A22: I20 | B22: Docentes ausentes en visitas sorpresa (promedio de 6 países en desarrollo) | C22: 0.19 | D22: % de docentes | E22: Estudio 2004-06 | F22: S24 | G22: 1 | H22: Banco Mundial.
A23: I21 | B23: India: docentes ausentes | C23: 0.25 | D23: % de docentes | E23: Estudio Banco Mundial | F23: S25 | G23: 1
A24: I22 | B24: Bangladés: docentes ausentes (primaria) | C24: 0.16 | D24: % de docentes | E24: Estudio Banco Mundial | F24: S25 | G24: 1
A25: I23 | B25: Uganda: docentes ausentes | C25: 0.27 | D25: % de docentes | E25: Estudio Banco Mundial | F25: S25 | G25: 1
A26: I24 | B26: Kenia: docentes ausentes | C26: 0.28 | D26: % de docentes | E26: Estudio Banco Mundial | F26: S25 | G26: 1
A27: I25 | B27: Perú: tiempo de ausencia docente | C27: 0.11 | D27: % del tiempo | E27: Estudio Banco Mundial | F27: S26 | G27: 1 | H27: El país más cercano culturalmente a México en la muestra.
A28: I26 | B28: EE.UU. y Finlandia: ausencias docentes (techo) | C28: 0.05 | D28: % (menor a) | E28: Referencia | F28: S25 | G28: 1 | H28: Cifra de columna de opinión; verificar con fuente primaria.
A29: I27 | B29: India (Seva Mandir): ausencia docente en línea base | C29: 0.35 | D29: % del tiempo | E29: Experimento aleatorio | F29: S23 | G29: 1
A30: I28 | B30: Hallazgo clave: el monitoreo SIN incentivos/consecuencias no funcionó | C30: Ver nota | D30: texto | E30: Experimento | F30: S23 | G30: 1, 3 | H30: Implicación de diseño: el sistema debe ir acompañado de un protocolo con consecuencias o apoyos.
A31: I29 | B31: Mejora en asistencia de personal con monitores biométricos (centros de salud, India) | C31: 0.15 | D31: % de mejora | E31: 2010-13 | F31: S23 | G31: 1 | H31: Efecto limitado y desgastable; no es escolar ni facial.
A32: C. Precisión del reconocimiento facial (NIST) - desventaja y condición de diseño
A33: I40 | B33: Exactitud típica de muchos algoritmos en todos los grupos demográficos | C33: 0.98 | D33: % (mínimo) | E33: FRVT 2019 | F33: S28 | G33: Desv. | H33: 98-99% a umbral FMR 0.03%. Diferencias absolutas suelen ser <1%.
A34: I41 | B34: Diferencial de falsos positivos en algoritmos menos precisos | C34: 100 | D34: veces (>) | E34: FRVT 2019 | F34: S28 | G34: Desv. | H34: Del peor al mejor grupo. Los mejores algoritmos tienen diferenciales indetectables.
A35: I42 | B35: Niños: mayor tasa de falsos positivos que adultos de mediana edad | C35: Sí | D35: texto | E35: FRVT 2019 | F35: S27 | G35: Desv. | H35: Relevante porque su población objetivo son menores. Exigir pruebas con niños del proveedor.
A36: D. Regulación y sanciones por reconocimiento facial en escuelas
A37: I50 | B37: Suecia (Skellefteå): multa GDPR por asistencia con reconocimiento facial | C37: 200000 | D37: SEK (~20,000 EUR) | E37: Ago-2019 | F37: S29 | G37: Desv. | H37: Piloto de 3 semanas con 22 alumnos. Tribunal confirmó la decisión.
A38: I51 | B38: Suecia: alumnos en el piloto sancionado | C38: 22 | D38: alumnos | E38: 2018-19 | F38: S29 | G38: Desv.
A39: I52 | B39: Suecia: motivo central | C39: Consentimiento inválido | D39: texto | E39: 2019 | F39: S30 | G39: Desv. | H39: Desequilibrio de poder escuela-alumno; había alternativas menos invasivas; faltó evaluación de impacto.
A40: I53 | B40: Reino Unido (Chelmer Valley, ~1,200 alumnos): reprimenda del ICO | C40: Reprimenda | D40: texto | E40: Jul-2024 | F40: S31 | G40: Desv. | H40: Sin DPIA ni consentimiento afirmativo. El ICO aclaró que NO prohíbe su uso, exige hacerlo bien.
A41: I54 | B41: Francia (Niza y Marsella): la CNIL se opuso a pilotos en liceos | C41: Oposición | D41: texto | E41: 2019 | F41: S32 | G41: Desv. | H41: Argumentos: intensifica sensación de vigilancia; hay medios menos intrusivos.

Sheet Calculadora
A1: Calculadora de tiempo docente recuperado
A2: Celdas amarillas = supuestos EDITABLES (no son datos oficiales). Reemplácelos con mediciones de su escuela.
A4: Concepto | B4: Valor | C4: Nota
A5: Grupos en el plantel | B5: 20 | C5: Supuesto: escuela mediana.
A6: Clases por grupo por día | B6: 6 | C6: Supuesto: un pase de lista por clase.
A7: Minutos que toma el pase manual por clase | B7: 4 | C7: Supuesto: medir con cronómetro una semana.
A8: Días lectivos al año | B8: 185 | C8: Supuesto: calendario SEP reciente (verificar el ciclo vigente).
A9: % del tiempo que el sistema automático recupera | B9: 0.8 | C9: Supuesto: el docente aún valida/corrige excepciones.
A10: Resultados
A11: Pases de lista por día | B11: =B5*B6 -> 120 | C11: Fórmula
A12: Minutos de pase de lista por día | B12: =B11*B7 -> 480 | C12: Fórmula
A13: Horas de pase de lista por año (manual) | B13: =B12*B8/60 -> 1480 | C13: Fórmula
A14: Horas recuperadas por año con sistema automático | B14: =B13*B9 -> 1184 | C14: Fórmula
A15: Equivalente en jornadas de 8 horas | B15: =B14/8 -> 148 | C15: Fórmula
A17: Ejemplo realista de llenado: 20 grupos, 6 clases/día, 4 min, 185 días, 80% recuperable (valores ya cargados arriba).

Sheet Fuentes
A1: Fuentes consultadas (06-oct-2026)
A2: Las cifras de prensa citan a organismos oficiales; se recomienda verificar en la fuente primaria antes de publicar.
A3: ID | B3: Título | C3: Organismo | D3: Tipo | E3: URL | F3: Nota de calidad
A4: S01 | B4: INEGI - Tabulados Educación 11: Tasa de abandono escolar por entidad y nivel (calculada por SEP con proyecciones CONAPO) | C4: INEGI / SEP | D4: Oficial | E4: https://www.inegi.org.mx/app/tabulados/pxwebv2/pxweb/es/Educacion/Educacion/Educacion_11.px/ | F4: Fuente primaria del indicador. Cifras 2023/24 reemplazadas por definitivas el 5-dic-2025.
A5: S02 | B5: Expansión (15-jul-2026): La SEP concluye otro ciclo sin evaluación a alumnos y sin datos sobre abandono escolar | C5: Expansión (cita SIGED-SEP, Mexicanos Primero) | D5: Prensa especializada | E5: https://politica.expansion.mx/mexico/2026/07/15/sep-concluye-ciclo-sin-evaluacion-a-alumnos | F5: Abandono 2019-20 vs 2023-24 y falta de actualización del SIGED desde 2023-24.
A6: S03 | B6: Xataka México: La SEP termina otro ciclo sin saber cuántos alumnos abandonaron la escuela | C6: Xataka México (cita Expansión/SIGED) | D6: Prensa | E6: https://www.xataka.com.mx/educacion/sep-termina-otro-ciclo-saber-cuantos-alumnos-abandonaron-escuela-mexico-sigue-medir-tamano-problema | F6: Confirma cifras de abandono por nivel 2019-20 a 2023-24.
A7: S04 | B7: UnoTV: Matrícula escolar en México 2020-2025 (datos INEGI) | C7: UnoTV (cita INEGI) | D7: Prensa | E7: https://www.unotv.com/nacional/matricula-escolar-mexico-inegi-ocde-2020-2025/ | F7: Matrícula 2023-24: 33,062,447.
A8: S05 | B8: Crónica (17-ago-2026): Desapariciones forzadas en México | C8: Crónica (cita RNPDNO) | D8: Prensa | E8: https://www.cronica.com.mx/nacional/2026/08/17/desapariciones-forzadas-en-mexico/ | F8: Serie anual RNPDNO a jun-2026; proporción por sexo/edad.
A9: S06 | B9: Crónica (14-sep-2026): Desapariciones forzadas en México - localizados | C9: Crónica (cita RNPDNO) | D9: Prensa | E9: https://www.cronica.com.mx/nacional/2026/09/14/desapariciones-forzadas-en-mexico-localizados/ | F9: 365,024 registros 2000-jun 2026; adolescentes mujeres con >90% de localización.
A10: S07 | B10: Boletín 29/2026 (30-ago-2026) - Somos MX / DDHH | C10: Somos MX (cita RNPDNO) | D10: ONG | E10: https://somosmx.org.mx/wp-content/uploads/2026/08/Boletin29.pdf.pdf | F10: 12,961 desapariciones en 2025; 35 por día; >5 son NNA; 18,104 NNA al 8-jun-2026.
A11: S08 | B11: UnoTV: CIDH alerta que desaparecen más niñas que niños en México | C11: UnoTV (cita CIDH, CNB, REDIM) | D11: Prensa | E11: https://www.unotv.com/nacional/cidh-alerta-que-desaparecen-mas-ninas-que-ninos-en-mexico/ | F11: 18,192 NNA 0-17 desaparecidos; 1,485 en 2026 (28% sin localizar a abril); REDIM >10,700 reportes en 2025.
A12: S09 | B12: SDP Noticias: El estado donde más desaparecen niños y adolescentes según la CIDH | C12: SDP Noticias (cita CIDH/RNPDNO) | D12: Prensa | E12: https://www.sdpnoticias.com/mexico/el-estado-donde-mas-desaparecen-ninos-y-adolescentes-en-mexico-segun-la-cidh/ | F12: Estado de México 4,113; CDMX 1,583 menores (corte jun-2025).
A13: S10 | B13: UnoTV: Adolescentes de 15 a 19 años vuelven a liderar las desapariciones en julio de 2026 | C13: UnoTV (cita RNPDNO) | D13: Prensa | E13: https://www.unotv.com/nacional/desapariciones-mexico-julio-2026-adolescentes/ | F13: Julio 2026: 1,070 reportes; 15-19 años: 193 mujeres y 137 hombres.
A14: S11 | B14: Gaceta Parlamentaria (11-nov-2025): proposición sobre desapariciones de NNA | C14: Cámara de Diputados | D14: Oficial (legislativo) | E14: https://gaceta.diputados.gob.mx/PDF/66/2025/nov/20251111-III-5.pdf | F14: 118,690 casos históricos NNA 0-17; 18,275 siguen desaparecidos (texto parcialmente legible).
... A36: S33 | B36: ADN40 (1-sep-2025): INEGI revela que 10.8% de los jóvenes desertan de la preparatoria | C36: ADN40 (cita INEGI) | D36: Prensa | E36: https://www.adn40.mx/mexico/2025-09-01/educacion-en-mexico-el-10-8-jovenes-desertan-preparatoria-inegi | F36: Cifras distintas a S02 (10.8% media superior; 2.9% secundaria; 5.7% superior). Verificar en S01.
